Workbook

Sheet Costos Indirectos y Fijos
A2: Tipo de Pieza | B2: Descripción | C2: Unidad | D2: Cantidad | E2: Costo Mensual (COP) | F2: Costo Total (COP) | G2: Costo Total (USD)
B3: Luz | C3: Mes | D3: 2 | E3: 235000 | F3: =D3*E3 -> 470000 | G3: =F3/'Costo Directos'!$S$1 -> 117.5 | K3: Fundición | L3: 1850000
B4: Agua | C4: Mes | D4: 2 | E4: 35000 | F4: =D4*E4 -> 70000 | G4: =F4/'Costo Directos'!$S$1 -> 17.5 | L4: 250000
B5: fotografias y videos | C5: Mes | D5: 2 | E5: 1500000 | F5: =D5*E5 -> 3000000 | G5: =F5/'Costo Directos'!$S$1 -> 750 | L5: 350000
B6: Arriendo | C6: Mes | D6: 2 | E6: 300000 | F6: =D6*E6 -> 600000 | G6: =F6/'Costo Directos'!$S$1 -> 150 | L6: 175000
B7: Transporte | C7: Mes | D7: 2 | E7: 300000 | F7: =D7*E7 -> 600000 | G7: =F7/'Costo Directos'!$S$1 -> 150 | L7: =200*3600 -> 720000
B8: Herramientas (depreciación) | C8: Mes | D8: 2 | E8: 600000 | F8: =D8*E8 -> 1200000 | G8: =F8/'Costo Directos'!$S$1 -> 300 | K8: Total | L8: =SUM(L3:L7) -> 3345000
B9: Empaque | C9: Pieza | D9: 100 | E9: 3800 | F9: =D9*E9 -> 380000 | G9: =F9/'Costo Directos'!$S$1 -> 95
B10: Tarjetas | C10: Pieza | D10: 400 | E10: 950 | F10: =D10*E10 -> 380000 | G10: =F10/'Costo Directos'!$S$1 -> 95
B11: Ayudante | C11: 1 | D11: Total | F11: 800000 | G11: =F11/'Costo Directos'!$S$1 -> 200
B12: Alquiler de vitrinas | C12: 2 | D12: Total | F12: 253000 | G12: =F12/'Costo Directos'!$S$1 -> 63.25
B13: Acidos, Alcohol, Etc | D13: Total | F13: 600000 | G13: =F13/'Costo Directos'!$S$1 -> 150
B14: Resinas para moldes | D14: Total | F14: 2100000 | G14: =F14/'Costo Directos'!$S$1 -> 525
B15: Precio de Plata Total | C15: gramos | D15: 950 | E15: 4200 | F15: =D15*E15 -> 3990000 | G15: =F15/'Costo Directos'!$S$1 -> 997.5
B16: Fundición | F16: 3345000 | G16: =F16/'Costo Directos'!$S$1 -> 836.25
B17: costo etiquetas y imprimador por etiquetas | C17: total | D17: 1 | E17: 560000 | F17: =D17*E17 -> 560000 | G17: =F17/'Costo Directos'!$S$1 -> 140
B18: Costo de trabajo hora por 10mil | C18: hrs | D18: 750 | F18: =D18*10000 -> 7500000 | G18: =F18/'Costo Directos'!$S$1 -> 1875
B19: Total Costos Indirectos | F19: =SUM(F3:F18) -> 25848000 | G19: =SUM(G3:G18) -> 6462
B20: Gramos Total Salidos Despues de Trabajo | F20: 509
B21: Precio por Gramo Sin Ganancia | F21: =F19/F20 -> 50781.925 | G21: =F21/'Costo Directos'!$S$1 -> 12.695481
B22: Precio por Gramo Gramo con Ganancia | F22: =F21*15%+F21 -> 58399.214 | G22: =F22/'Costo Directos'!$S$1 -> 14.599804

Sheet Costo Directos
R1: Tipo de Cambio | S1: 4000
R2: PGC | S2: ='Costos Indirectos y Fijos'!F22 -> 58399.214 | U2: Piedra | V2: Precios Piedras
F3: Piedra 1 | I3: Piedra 2 | R3: Impuesto | S3: 0.19 | U3: Diamante | V3: 75000
A4: # de Pieza | B4: Nombre de Pieza | C4: Unidad | D4: Cantidad | E4: PCG | F4: Tipo | G4: Unidad | H4: Costo | I4: Tipo | J4: Unidad | K4: Costo | L4: Piedras Totales | M4: Esmalteo | N4: Unitario (COP) | O4: Impuesto | P4: Cadena | Q4: Total (COP) | R4: Total (USD) | U4: Esmeralda | V4: 38000
A5: 1 | B5: Hoja de Mapple Olive con Rubí | C5: Gramos | D5: 5.534 | E5: =D5*$S$2 -> 323181.25 | F5: Rubí | G5: 2 | H5: =VLOOKUP(F5,$U$2:$V$17,2,FALSE) -> 50000 | I5: No | L5: =(G5*H5)+(J5*K5) -> 100000 | M5: 50000 | N5: =E5+L5+M5 -> 473181.25 | O5: =N5+(N5*$S$3) -> 563085.69 | Q5: =O5+P5 -> 563085.69 | R5: =Q5/$S$1 -> 140.77142 | U5: Rubí | V5: 50000
A6: 2 | B6: Dije Bambú | C6: Gramos | D6: 1.87 | E6: =D6*$S$2 -> 109206.53 | F6: Citrino | G6: 2 | H6: =VLOOKUP(F6,$U$2:$V$17,2,FALSE) -> 25000 | I6: Amatista | J6: 3 | K6: =VLOOKUP(I6,$U$2:$V$17,2,FALSE) -> 25000 | L6: =(G6*H6)+(J6*K6) -> 125000 | M6: 50000 | N6: =E6+L6+M6 -> 284206.53 | O6: =N6+(N6*$S$3) -> 338205.77 | P6: 45000 | Q6: =O6+P6 -> 383205.77 | R6: =Q6/$S$1 -> 95.801443 | U6: Zafiro | V6: 50000
A7: 3 | B7: Aretes Transformers Mapple Rojo Con Esmeralda | C7: Gramos | D7: 5.712 | Q7: =Q8+Q9 -> 546895.81 | R7: =Q7/$S$1 -> 136.72395 | U7: Granate Verde | V7: 30000
A8: 3.1 | B8: Parte 1 Dijes | C8: Gramos | D8: 4.373 | E8: =D8*$S$2 -> 255379.76 | F8: Esmeralda | G8: 2 | H8: =VLOOKUP(F8,$U$2:$V$17,2,FALSE) -> 38000 | I8: No | L8: =(G8*H8)+(J8*K8) -> 76000 | M8: 50000 | N8: =E8+L8+M8 -> 381379.76 | O8: =N8+(N8*$S$3) -> 453841.92 | P8: 0 | Q8: =O8+P8 -> 453841.92 | R8: =Q8/$S$1 -> 113.46048 | U8: Acuamarina | V8: 45000
A9: 3.2 | B9: Parte 2 Aretes | C9: Gramos | D9: 1.339 | E9: =D9*$S$2 -> 78196.548 | F9: No | I9: No | L9: =(G9*H9)+(J9*K9) -> 0 | M9: 0 | N9: =E9+L9+M9 -> 78196.548 | O9: =N9+(N9*$S$3) -> 93053.892 | P9: 0 | Q9: =O9+P9 -> 93053.892 | R9: =Q9/$S$1 -> 23.263473 | U9: Zafiro Paparadga | V9: 100000
A10: 4 | B10: Dije Rojo Verde Mapple con 2 Zafiros | C10: Gramos | D10: 3.15 | E10: =D10*$S$2 -> 183957.52 | F10: Zafiro | G10: 2 | H10: =VLOOKUP(F10,$U$2:$V$17,2,FALSE) -> 50000 | I10: No | L10: =(G10*H10)+(J10*K10) -> 100000 | M10: 50000 | N10: =E10+L10+M10 -> 333957.52 | O10: =N10+(N10*$S$3) -> 397409.45 | P10: 45000 | Q10: =O10+P10 -> 442409.45 | R10: =Q10/$S$1 -> 110.60236 | U10: Granate Rojo | V10: 25000
A11: 5 | B11: Bambu Amarillo Verde Con Esmeralda | C11: Gramos | D11: 2.69 | E11: =D11*$S$2 -> 157093.89 | F11: Esmeralda | G11: 2 | H11: =VLOOKUP(F11,$U$2:$V$17,2,FALSE) -> 38000 | I11: No | L11: =(G11*H11)+(J11*K11) -> 76000 | M11: 50000 | N11: =E11+L11+M11 -> 283093.89 | O11: =N11+(N11*$S$3) -> 336881.72 | P11: 0 | Q11: =O11+P11 -> 336881.72 | R11: =Q11/$S$1 -> 84.220431 | U11: Amatista | V11: 25000
A12: 6 | B12: Bambu Verde 84 con Zafiros | C12: Gramos | D12: 3.059 | E12: =D12*$S$2 -> 178643.2 | F12: Zafiro | G12: 2 | H12: =VLOOKUP(F12,$U$2:$V$17,2,FALSE) -> 50000 | I12: No | L12: =(G12*H12)+(J12*K12) -> 100000 | M12: 50000 | N12: =E12+L12+M12 -> 328643.2 | O12: =N12+(N12*$S$3) -> 391085.4 | P12: 0 | Q12: =O12+P12 -> 391085.4 | R12: =Q12/$S$1 -> 97.771351 | U12: Citrino | V12: 25000
A13: 7 | B13: Broche Pensamientos con Zafiro Paparadga | C13: Gramos | D13: 10.344 | E13: =D13*$S$2 -> 604081.47 | F13: Zafiro Paparadga | G13: 1 | H13: =VLOOKUP(F13,$U$2:$V$17,2,FALSE) -> 100000 | L13: =(G13*H13)+(J13*K13) -> 100000 | M13: 50000 | N13: =E13+L13+M13 -> 754081.47 | O13: =N13+(N13*$S$3) -> 897356.95 | P13: 0 | Q13: =O13+P13 -> 897356.95 | R13: =Q13/$S$1 -> 224.33924 | U13: Peridoto | V13: 25000
A14: 8 | B14: Bambú Verde 83 con Esmeralda | C14: Gramos | D14: 1.91 | E14: =D14*$S$2 -> 111542.5 | F14: Esmeralda | G14: 2 | H14: =VLOOKUP(F14,$U$2:$V$17,2,FALSE) -> 38000 | L14: =(G14*H14)+(J14*K14) -> 76000 | M14: 50000 | N14: =E14+L14+M14 -> 237542.5 | O14: =N14+(N14*$S$3) -> 282675.57 | P14: 0 | Q14: =O14+P14 -> 282675.57 | R14: =Q14/$S$1 -> 70.668893 | U14: Tanzanita | V14: 35000
A15: 9 | B15: Bambú Azul Claro con Acuamarina | C15: Gramos | D15: 1.909 | E15: =D15*$S$2 -> 111484.1 | F15: Acuamarina | G15: 2 | H15: =VLOOKUP(F15,$U$2:$V$17,2,FALSE) -> 45000 | L15: =(G15*H15)+(J15*K15) -> 90000 | M15: 50000 | N15: =E15+L15+M15 -> 251484.1 | O15: =N15+(N15*$S$3) -> 299266.08 | P15: 0 | Q15: =O15+P15 -> 299266.08 | R15: =Q15/$S$1 -> 74.81652 | U15: CZ 1mm | V15: 300
A16: 10 | B16: Bambú Amatista con 2 Rubíes | C16: Gramos | D16: 3.1 | E16: =D16*$S$2 -> 181037.56 | F16: Rubí | G16: 2 | H16: =VLOOKUP(F16,$U$2:$V$17,2,FALSE) -> 50000 | L16: =(G16*H16)+(J16*K16) -> 100000 | M16: 50000 | N16: =E16+L16+M16 -> 331037.56 | O16: =N16+(N16*$S$3) -> 393934.7 | P16: 0 | Q16: =O16+P16 -> 393934.7 | R16: =Q16/$S$1 -> 98.483675 | U16: CZ | V16: 2000
A17: 11 | B17: Bambú Naranja con 2 Rubíes | C17: Gramos | D17: 1.929 | E17: =D17*$S$2 -> 112652.08 | F17: Rubí | G17: 2 | H17: =VLOOKUP(F17,$U$2:$V$17,2,FALSE) -> 50000 | L17: =(G17*H17)+(J17*K17) -> 100000 | M17: 50000 | N17: =E17+L17+M17 -> 262652.08 | O17: =N17+(N17*$S$3) -> 312555.98 | P17: 0 | Q17: =O17+P17 -> 312555.98 | R17: =Q17/$S$1 -> 78.138995 | U17: Corindon Laboratorio | V17: 2500
A18: 12 | B18: Bambú Amarillo con 2 Peridotos | C18: Gramos | D18: 3.23 | E18: =D18*$S$2 -> 188629.46 | F18: Peridoto | G18: 2 | H18: =VLOOKUP(F18,$U$2:$V$17,2,FALSE) -> 25000 | L18: =(G18*H18)+(J18*K18) -> 50000 | M18: 50000 | N18: =E18+L18+M18 -> 288629.46 | O18: =N18+(N18*$S$3) -> 343469.06 | P18: 0 | Q18: =O18+P18 -> 343469.06 | R18: =Q18/$S$1 -> 85.867265
A19: 13 | B19: Maple Hoja Naranja SM con 2 Esmeraldas | C19: Gramos | D19: 3.213 | E19: =D19*$S$2 -> 187636.68 | F19: Esmeralda | G19: 2 | H19: =VLOOKUP(F19,$U$2:$V$17,2,FALSE) -> 38000 | L19: =(G19*H19)+(J19*K19) -> 76000 | M19: 50000 | N19: =E19+L19+M19 -> 313636.68 | O19: =N19+(N19*$S$3) -> 373227.64 | P19: 0 | Q19: =O19+P19 -> 373227.64 | R19: =Q19/$S$1 -> 93.306911
A20: 14 | B20: Dije Bambú Verde 84 con 5 Rubíes | C20: Gramos | D20: 1.931 | E20: =D20*$S$2 -> 112768.88 | F20: Rubí | G20: 5 | H20: =VLOOKUP(F20,$U$2:$V$17,2,FALSE) -> 50000 | L20: =(G20*H20)+(J20*K20) -> 250000 | M20: 50000 | N20: =E20+L20+M20 -> 412768.88 | O20: =N20+(N20*$S$3) -> 491194.97 | P20: 45000 | Q20: =O20+P20 -> 536194.97 | R20: =Q20/$S$1 -> 134.04874
A21: 15 | B21: Dije Pensamiento Naranja con 4 Esmeraldas | C21: Gramos | D21: 2.449 | E21: =D21*$S$2 -> 143019.68 | F21: Esmeralda | G21: 4 | H21: =VLOOKUP(F21,$U$2:$V$17,2,FALSE) -> 38000 | L21: =(G21*H21)+(J21*K21) -> 152000 | M21: 50000 | N21: =E21+L21+M21 -> 345019.68 | O21: =N21+(N21*$S$3) -> 410573.41 | P21: 45000 | Q21: =O21+P21 -> 455573.41 | R21: =Q21/$S$1 -> 113.89335
A22: 16 | B22: Hoja Maple Color 83 con 2 Zafiros | C22: Gramos | D22: 5.69 | E22: =D22*$S$2 -> 332291.53 | F22: Zafiro | G22: 2 | H22: =VLOOKUP(F22,$U$2:$V$17,2,FALSE) -> 50000 | L22: =(G22*H22)+(J22*K22) -> 100000 | M22: 50000 | N22: =E22+L22+M22 -> 482291.53 | O22: =N22+(N22*$S$3) -> 573926.92 | P22: 0 | Q22: =O22+P22 -> 573926.92 | R22: =Q22/$S$1 -> 143.48173
A23: 17 | B23: Pensamiento Morado Amarillo con 2 Rubíes | C23: Gramos | D23: 4 | E23: =D23*$S$2 -> 233596.86 | F23: Rubí | G23: 2 | H23: =VLOOKUP(F23,$U$2:$V$17,2,FALSE) -> 50000 | L23: =(G23*H23)+(J23*K23) -> 100000 | M23: 50000 | N23: =E23+L23+M23 -> 383596.86 | O23: =N23+(N23*$S$3) -> 456480.26 | P23: 0 | Q23: =O23+P23 -> 456480.26 | R23: =Q23/$S$1 -> 114.12006
A24: 18 | B24: Maple Naranja Rosado con 2 Esmeraldas | C24: Gramos | D24: 7.444 | E24: =D24*$S$2 -> 434723.75 | F24: Esmeralda | G24: 2 | H24: =VLOOKUP(F24,$U$2:$V$17,2,FALSE) -> 38000 | L24: =(G24*H24)+(J24*K24) -> 76000 | M24: 50000 | N24: =E24+L24+M24 -> 560723.75 | O24: =N24+(N24*$S$3) -> 667261.26 | P24: 0 | Q24: =O24+P24 -> 667261.26 | R24: =Q24/$S$1 -> 166.81532
A25: 19 | B25: Mapple Verde Amarillo con 2 Granates | C25: Gramos | D25: 7.478 | E25: =D25*$S$2 -> 436709.32 | F25: Granate Rojo | G25: 2 | H25: =VLOOKUP(F25,$U$2:$V$17,2,FALSE) -> 25000 | L25: =(G25*H25)+(J25*K25) -> 50000 | M25: 50000 | N25: =E25+L25+M25 -> 536709.32 | O25: =N25+(N25*$S$3) -> 638684.09 | P25: 0 | Q25: =O25+P25 -> 638684.09 | R25: =Q25/$S$1 -> 159.67102
A26: 20 | B26: Pensamiento Azul Claro con 4 Zafiros Dije | C26: Gramos | D26: 2.417 | E26: =D26*$S$2 -> 141150.9 | F26: Zafiro | G26: 4 | H26: =VLOOKUP(F26,$U$2:$V$17,2,FALSE) -> 50000 | L26: =(G26*H26)+(J26*K26) -> 200000 | M26: 50000 | N26: =E26+L26+M26 -> 391150.9 | O26: =N26+(N26*$S$3) -> 465469.57 | P26: 45000 | Q26: =O26+P26 -> 510469.57 | R26: =Q26/$S$1 -> 127.61739
A27: 21 | B27: Orquidea Grande con Esmeralda 1 Kilate | C27: Gramos | E27: =D27*$S$2 -> 0 | H27: =VLOOKUP(F27,$U$2:$V$17,2,FALSE) -> #N/A | L27: =(G27*H27)+(J27*K27) -> #N/A | M27: 50000 | N27: =E27+L27+M27 -> #N/A | O27: =N27+(N27*$S$3) -> #N/A | P27: 0 | Q27: 2500000 | R27: =Q27/$S$1 -> 625
A28: 22 | B28: Pensamiento Morado con 2 Rubíes | C28: Gramos | D28: 3.956 | E28: =D28*$S$2 -> 231027.29 | F28: Rubí | G28: 2 | H28: =VLOOKUP(F28,$U$2:$V$17,2,FALSE) -> 50000 | L28: =(G28*H28)+(J28*K28) -> 100000 | M28: 50000 | N28: =E28+L28+M28 -> 381027.29 | O28: =N28+(N28*$S$3) -> 453422.48 | P28: 0 | Q28: =O28+P28 -> 453422.48 | R28: =Q28/$S$1 -> 113.35562
A29: 23 | B29: Pensamiento Rojo Amarillo con 2 Zafiros Rosados | C29: Gramos | D29: 4 | E29: =D29*$S$2 -> 233596.86 | F29: Zafiro | G29: 2 | H29: =VLOOKUP(F29,$U$2:$V$17,2,FALSE) -> 50000 | L29: =(G29*H29)+(J29*K29) -> 100000 | M29: 50000 | N29: =E29+L29+M29 -> 383596.86 | O29: =N29+(N29*$S$3) -> 456480.26 | P29: 0 | Q29: =O29+P29 -> 456480.26 | R29: =Q29/$S$1 -> 114.12006
A30: 24 | B30: Maple Hoja Roja con 2 Zafiros Amarillos | C30: Gramos | D30: 3.22 | E30: =D30*$S$2 -> 188045.47 | F30: Zafiro | G30: 2 | H30: =VLOOKUP(F30,$U$2:$V$17,2,FALSE) -> 50000 | L30: =(G30*H30)+(J30*K30) -> 100000 | M30: 50000 | N30: =E30+L30+M30 -> 338045.47 | O30: =N30+(N30*$S$3) -> 402274.11 | P30: 0 | Q30: =O30+P30 -> 402274.11 | R30: =Q30/$S$1 -> 100.56853
A31: 25 | B31: Pensamientos Amarillos con Tsavorita | C31: Gramos | D31: 4.327 | E31: =D31*$S$2 -> 252693.4 | F31: Zafiro | G31: 2 | H31: =VLOOKUP(F31,$U$2:$V$17,2,FALSE) -> 50000 | L31: =(G31*H31)+(J31*K31) -> 100000 | M31: 50000 | N31: =E31+L31+M31 -> 402693.4 | O31: =N31+(N31*$S$3) -> 479205.15 | P31: 0 | Q31: =O31+P31 -> 479205.15 | R31: =Q31/$S$1 -> 119.80129
A32: 26 | B32: Dije Morado con 4 Diamantes | C32: Gramos | D32: 2.417 | E32: =D32*$S$2 -> 141150.9 | F32: Diamante | G32: 4 | H32: =VLOOKUP(F32,$U$2:$V$17,2,FALSE) -> 75000 | L32: =(G32*H32)+(J32*K32) -> 300000 | M32: 50000 | N32: =E32+L32+M32 -> 491150.9 | O32: =N32+(N32*$S$3) -> 584469.57 | P32: 45000 | Q32: =O32+P32 -> 629469.57 | R32: =Q32/$S$1 -> 157.36739
A33: 27 | B33: Bambú Doble con 4 CZ y 8 Corindon | C33: Gramos | D33: 5.229 | E33: =D33*$S$2 -> 305369.49 | F33: CZ | G33: 4 | H33: =VLOOKUP(F33,$U$2:$V$17,2,FALSE) -> 2000 | I33: Corindon Laboratorio | J33: 8 | K33: =VLOOKUP(I33,$U$2:$V$17,2,FALSE) -> 2500 | L33: =(G33*H33)+(J33*K33) -> 28000 | M33: 50000 | N33: =E33+L33+M33 -> 383369.49 | O33: =N33+(N33*$S$3) -> 456209.69 | P33: 0 | Q33: =O33+P33 -> 456209.69 | R33: =Q33/$S$1 -> 114.05242
A34: 28 | B34: Manzanilla Blanca con Mariposas con 2CZ 8mm | C34: Gramos | D34: 11.397 | E34: =D34*$S$2 -> 665575.84 | F34: CZ | G34: 6 | H34: =VLOOKUP(F34,$U$2:$V$17,2,FALSE) -> 2000 | L34: =(G34*H34)+(J34*K34) -> 12000 | M34: 50000 | N34: =E34+L34+M34 -> 727575.84 | O34: =N34+(N34*$S$3) -> 865815.25 | P34: 0 | Q34: =O34+P34 -> 865815.25 | R34: =Q34/$S$1 -> 216.45381
A35: 29 | B35: Orquidea Roja Amarilla con 2 CZ Amarillo | C35: Gramos | D35: 5.316 | E35: =D35*$S$2 -> 310450.22 | F35: CZ | G35: 2 | H35: =VLOOKUP(F35,$U$2:$V$17,2,FALSE) -> 2000 | L35: =(G35*H35)+(J35*K35) -> 4000 | M35: 50000 | N35: =E35+L35+M35 -> 364450.22 | O35: =N35+(N35*$S$3) -> 433695.76 | P35: 0 | Q35: =O35+P35 -> 433695.76 | R35: =Q35/$S$1 -> 108.42394
A36: 30 | B36: Dije Maple Naranjo con 2 Esmeraldas | C36: Gramos | D36: 3.15 | E36: =D36*$S$2 -> 183957.52 | F36: Esmeralda | G36: 2 | H36: =VLOOKUP(F36,$U$2:$V$17,2,FALSE) -> 38000 | L36: =(G36*H36)+(J36*K36) -> 76000 | M36: 50000 | N36: =E36+L36+M36 -> 309957.52 | O36: =N36+(N36*$S$3) -> 368849.45 | P36: 45000 | Q36: =O36+P36 -> 413849.45 | R36: =Q36/$S$1 -> 103.46236
A37: 31 | B37: Maple Hoja 20a con 2 Esmeraldas | C37: Gramos | D37: 5.592 | E37: =D37*$S$2 -> 326568.41 | F37: Esmeralda | G37: 2 | H37: =VLOOKUP(F37,$U$2:$V$17,2,FALSE) -> 38000 | L37: =(G37*H37)+(J37*K37) -> 76000 | M37: 50000 | N37: =E37+L37+M37 -> 452568.41 | O37: =N37+(N37*$S$3) -> 538556.4 | P37: 0 | Q37: =O37+P37 -> 538556.4 | R37: =Q37/$S$1 -> 134.6391
A38: 32 | B38: Maple Hoja Verde 83 con 2 Zafiros | C38: Gramos | D38: 7.399 | E38: =D38*$S$2 -> 432095.79 | F38: Zafiro | G38: 2 | H38: =VLOOKUP(F38,$U$2:$V$17,2,FALSE) -> 50000 | L38: =(G38*H38)+(J38*K38) -> 100000 | M38: 50000 | N38: =E38+L38+M38 -> 582095.79 | O38: =N38+(N38*$S$3) -> 692693.98 | P38: 0 | Q38: =O38+P38 -> 692693.98 | R38: =Q38/$S$1 -> 173.1735
A39: 33 | B39: Aretes Transformers Mapple Verde Amarillo con 2 Zafiros | C39: Gramos | E39: =D39*$S$2 -> 0 | H39: =VLOOKUP(F39,$U$2:$V$17,2,FALSE) -> #N/A | L39: =(G39*H39)+(J39*K39) -> #N/A | M39: 50000 | N39: =E39+L39+M39 -> #N/A | O39: =N39+(N39*$S$3) -> #N/A | P39: 0 | Q39: =Q40+Q41 -> 627924.58 | R39: =Q39/$S$1 -> 156.98115
A40: 33.1 | B40: Parte 1 Dijes | C40: Gramos | D40: 4.244 | E40: =D40*$S$2 -> 247846.26 | F40: Zafiro | G40: 2 | H40: =VLOOKUP(F40,$U$2:$V$17,2,FALSE) -> 50000 | L40: =(G40*H40)+(J40*K40) -> 100000 | M40: 50000 | N40: =E40+L40+M40 -> 397846.26 | O40: =N40+(N40*$S$3) -> 473437.06 | P40: 0 | Q40: =O40+P40 -> 473437.06 | R40: =Q40/$S$1 -> 118.35926
...

Sheet Costos Total
A1: Tipo de Pieza | B1: Descripción | C1: Costo (COP) | D1: Costo (USD)
B2: Costos Directos
B3: Costos Indirectos
B4: Costo Total de Producción

Sheet Sheet4
C2: peso de compra | D2: peso de salida
B3: Precio metal Gramo de Compra
